<?xml version="1.0" ?>
<sdf version="1.6">
  <model name="camera_robot">
    <!-- 机器人底盘 -->
    <link name="base_link">
      <pose>0 0 0.1 0 0 0</pose>
      
      <inertial>
        <mass>5.0</mass>
        <inertia>
          <ixx>0.1</ixx>
          <ixy>0</ixy>
          <ixz>0</ixz>
          <iyy>0.1</iyy>
          <iyz>0</iyz>
          <izz>0.1</izz>
        </inertia>
      </inertial>
      
      <collision name="collision">
        <geometry>
          <box>
            <size>0.5 0.3 0.2</size>
          </box>
        </geometry>
      </collision>
      
      <visual name="visual">
        <geometry>
          <box>
            <size>0.5 0.3 0.2</size>
          </box>
        </geometry>
        <material>
          <ambient>0.8 0.2 0.2 1</ambient>
          <diffuse>0.8 0.2 0.2 1</diffuse>
          <specular>0.1 0.1 0.1 1</specular>
        </material>
      </visual>
    </link>
    
    <!-- 左轮 -->
    <link name="left_wheel">
      <pose>-0.2 0.2 0.05 1.5708 0 0</pose>
      
      <inertial>
        <mass>0.5</mass>
        <inertia>
          <ixx>0.01</ixx>
          <ixy>0</ixy>
          <ixz>0</ixz>
          <iyy>0.01</iyy>
          <iyz>0</iyz>
          <izz>0.01</izz>
        </inertia>
      </inertial>
      
      <collision name="collision">
        <geometry>
          <cylinder>
            <radius>0.08</radius>
            <length>0.05</length>
          </cylinder>
        </geometry>
      </collision>
      
      <visual name="visual">
        <geometry>
          <cylinder>
            <radius>0.08</radius>
            <length>0.05</length>
          </cylinder>
        </geometry>
        <material>
          <ambient>0.1 0.1 0.1 1</ambient>
          <diffuse>0.1 0.1 0.1 1</diffuse>
          <specular>0.5 0.5 0.5 1</specular>
        </material>
      </visual>
    </link>
    
    <!-- 右轮 -->
    <link name="right_wheel">
      <pose>-0.2 -0.2 0.05 1.5708 0 0</pose>
      
      <inertial>
        <mass>0.5</mass>
        <inertia>
          <ixx>0.01</ixx>
          <ixy>0</ixy>
          <ixz>0</ixz>
          <iyy>0.01</iyy>
          <iyz>0</iyz>
          <izz>0.01</izz>
        </inertia>
      </inertial>
      
      <collision name="collision">
        <geometry>
          <cylinder>
            <radius>0.08</radius>
            <length>0.05</length>
          </cylinder>
        </geometry>
      </collision>
      
      <visual name="visual">
        <geometry>
          <cylinder>
            <radius>0.08</radius>
            <length>0.05</length>
          </cylinder>
        </geometry>
        <material>
          <ambient>0.1 0.1 0.1 1</ambient>
          <diffuse>0.1 0.1 0.1 1</diffuse>
          <specular>0.5 0.5 0.5 1</specular>
        </material>
      </visual>
    </link>
    
    <!-- RGBD相机 -->
    <link name="camera_link">
      <pose>0.2 0 0.3 0 0 0</pose>
      
      <inertial>
        <mass>0.2</mass>
        <inertia>
          <ixx>0.001</ixx>
          <ixy>0</ixy>
          <ixz>0</ixz>
          <iyy>0.001</iyy>
          <iyz>0</iyz>
          <izz>0.001</izz>
        </inertia>
      </inertial>
      
      <sensor name="rgbd_camera" type="camera">
        <camera name="camera">
          <horizontal_fov>1.047</horizontal_fov>
          <image>
            <width>640</width>
            <height>480</height>
            <format>R8G8B8</format>
          </image>
          <clip>
            <near>0.1</near>
            <far>100</far>
          </clip>
        </camera>
        <always_on>true</always_on>
        <update_rate>30</update_rate>
        
        <plugin name="camera_controller" filename="libgazebo_ros_camera.so">
          <ros>
            <namespace>/camera_robot</namespace>
            <argument>image_raw:=rgb/image_raw</argument>
            <argument>camera_info:=rgb/camera_info</argument>
          </ros>
          <camera_name>rgbd_camera</camera_name>
          <frame_name>camera_link</frame_name>
          <hack_baseline>0.07</hack_baseline>
        </plugin>
      </sensor>
      
      <visual name="visual">
        <geometry>
          <box>
            <size>0.05 0.05 0.05</size>
          </box>
        </geometry>
        <material>
          <ambient>0 0 1 1</ambient>
          <diffuse>0 0 1 1</diffuse>
        </material>
      </visual>
    </link>
    
    <!-- 轮子连接关节 -->
    <joint name="left_wheel_joint" type="revolute">
      <parent>base_link</parent>
      <child>left_wheel</child>
      <axis>
        <xyz>0 0 1</xyz>
      </axis>
    </joint>
    
    <joint name="right_wheel_joint" type="revolute">
      <parent>base_link</parent>
      <child>right_wheel</child>
      <axis>
        <xyz>0 0 1</xyz>
      </axis>
    </joint>
    
    <!-- 相机连接关节 -->
    <joint name="camera_joint" type="fixed">
      <parent>base_link</parent>
      <child>camera_link</child>
    </joint>
    
    <!-- Gazebo插件 -->
    <plugin name="differential_drive_controller" filename="libgazebo_ros_diff_drive.so">
      <ros>
        <namespace>/camera_robot</namespace>
      </ros>
      <left_joint>left_wheel_joint</left_joint>
      <right_joint>right_wheel_joint</right_joint>
      <wheel_separation>0.4</wheel_separation>
      <wheel_diameter>0.16</wheel_diameter>
      <wheel_torque>10</wheel_torque>
      <command_topic>cmd_vel</command_topic>
      <odometry_topic>odom</odometry_topic>
      <odometry_frame>odom</odometry_frame>
      <robot_base_frame>base_link</robot_base_frame>
      <publish_odom>true</publish_odom>
      <publish_odom_tf>true</publish_odom_tf>
      <publish_wheel_tf>true</publish_wheel_tf>
    </plugin>
  </model>
</sdf>